<?xml version="1.0" encoding="utf-8"?>
<!-- =================================================================================== -->
<!-- |    This document was autogenerated by xacro from /home/ram/Projects/Project-Interstellar/src/mecademic_description/urdf/meca_500_r3.urdf.xacro | -->
<!-- |    EDITING THIS FILE BY HAND IS NOT RECOMMENDED                                 | -->
<!-- =================================================================================== -->
<robot name="meca_500_r3">
    <!-- Base link is the center of the robot's bottom plate -->
    <link name="world"/>
    <joint name="world_joint" type="fixed">
        <parent link="world" />
        <child link="meca_base_link" />
        <origin rpy="0.0 0.0 0.0" xyz="0.0 0.0 0.0" />
    </joint>
    <link name="meca_base_link">
        <visual>
            <origin rpy="0 0 0" xyz="0 0 0" />
            <geometry>
                <mesh filename="package://mecademic_description/meshes/meca_500_r3_base.dae" />
            </geometry>
        </visual>
        <collision>
            <origin rpy="0 0 0" xyz="0 0 0" />
            <geometry>
                <mesh filename="package://mecademic_description/meshes/meca_500_r3_base_collision.stl" />
            </geometry>
        </collision>

        <inertial>
            <mass value="0.1" />
            <inertia ixx="0.03" ixy="0.0" ixz="0.0" iyy="0.03" iyz="0.0" izz="0.03" />
        </inertial>

    </link>
    <!-- Joint 1 -->
    <link name="meca_axis_1_link">
        <visual>
            <origin rpy="0 0 0" xyz="0 0 0" />
            <geometry>
                <mesh filename="package://mecademic_description/meshes/meca_500_r3_j1.dae" />
            </geometry>
        </visual>
        <collision>
            <origin rpy="0 0 0" xyz="0 0 0" />
            <geometry>
                <mesh filename="package://mecademic_description/meshes/meca_500_r3_j1_collision.stl" />
            </geometry>
        </collision>

        <inertial>
            <mass value="0.1" />
            <inertia ixx="0.03" ixy="0.0" ixz="0.0" iyy="0.03" iyz="0.0" izz="0.03" />
        </inertial>

    </link>
    <joint name="meca_axis_1_joint" type="revolute">
        <origin rpy="0 0 0" xyz="0.012498 0 0.091" />
        <parent link="meca_base_link" />
        <child link="meca_axis_1_link" />
        <axis xyz="0 0 1" />
        <limit effort="10.0" lower="-3.05433" upper="3.05433" velocity="2.61799" />
    </joint>
    <!-- Joint 2 -->
    <link name="meca_axis_2_link">
        <visual>
            <origin rpy="0 0 0" xyz="0 0 0" />
            <geometry>
                <mesh filename="package://mecademic_description/meshes/meca_500_r3_j2.dae" />
            </geometry>
        </visual>
        <collision>
            <origin rpy="0 0 0" xyz="0 0 0" />
            <geometry>
                <mesh filename="package://mecademic_description/meshes/meca_500_r3_j2_collision.stl" />
            </geometry>
        </collision>

        <inertial>
            <mass value="0.1" />
            <inertia ixx="0.03" ixy="0.0" ixz="0.0" iyy="0.03" iyz="0.0" izz="0.03" />
        </inertial>

    </link>
    <joint name="meca_axis_2_joint" type="revolute">
        <origin rpy="0 0 0" xyz="0 0 0.044" />
        <parent link="meca_axis_1_link" />
        <child link="meca_axis_2_link" />
        <axis xyz="0 1 0" />
        <limit effort="10.0" lower="-1.22173048" upper="1.5708" velocity="2.61799" />
    </joint>
    <!-- Joint 3 -->
    <link name="meca_axis_3_link">
        <visual>
            <origin rpy="0 0 0" xyz="0 0 0" />
            <geometry>
                <mesh filename="package://mecademic_description/meshes/meca_500_r3_j3.dae" />
            </geometry>
        </visual>
        <collision>
            <origin rpy="0 0 0" xyz="0 0 0" />
            <geometry>
                <mesh filename="package://mecademic_description/meshes/meca_500_r3_j3_collision.stl" />
            </geometry>
        </collision>

        <inertial>
            <mass value="0.1" />
            <inertia ixx="0.03" ixy="0.0" ixz="0.0" iyy="0.03" iyz="0.0" izz="0.03" />
        </inertial>

    </link>
    <joint name="meca_axis_3_joint" type="revolute">
        <origin rpy="0 0 0" xyz="0 0 0.135" />
        <parent link="meca_axis_2_link" />
        <child link="meca_axis_3_link" />
        <axis xyz="0 1 0" />
        <limit effort="10.0" lower="-2.35619" upper="1.22173048" velocity="3.14159" />
    </joint>
    <!-- Joint 4 -->
    <link name="meca_axis_4_link">
        <visual>
            <origin rpy="0 0 0" xyz="0 0 0" />
            <geometry>
                <mesh filename="package://mecademic_description/meshes/meca_500_r3_j4.dae" />
            </geometry>
        </visual>
        <collision>
            <origin rpy="0 0 0" xyz="0 0 0" />
            <geometry>
                <mesh filename="package://mecademic_description/meshes/meca_500_r3_j4_collision.stl" />
            </geometry>
        </collision>

        <inertial>
            <mass value="0.1" />
            <inertia ixx="0.03" ixy="0.0" ixz="0.0" iyy="0.03" iyz="0.0" izz="0.03" />
        </inertial>

    </link>
    <joint name="meca_axis_4_joint" type="revolute">
        <origin rpy="0 0 0" xyz="0 0 0.038" />
        <parent link="meca_axis_3_link" />
        <child link="meca_axis_4_link" />
        <axis xyz="1 0 0" />
        <limit effort="10.0" lower="-2.96706" upper="2.96706" velocity="5.23599" />
    </joint>
    <!-- Joint 5 -->
    <link name="meca_axis_5_link">
        <visual>
            <origin rpy="0 0 0" xyz="0 0 0" />
            <geometry>
                <mesh filename="package://mecademic_description/meshes/meca_500_r3_j5.dae" />
            </geometry>
        </visual>
        <collision>
            <origin rpy="0 0 0" xyz="0 0 0" />
            <geometry>
                <mesh filename="package://mecademic_description/meshes/meca_500_r3_j5_collision.stl" />
            </geometry>
        </collision>

        <inertial>
            <mass value="0.1" />
            <inertia ixx="0.03" ixy="0.0" ixz="0.0" iyy="0.03" iyz="0.0" izz="0.03" />
        </inertial>

    </link>
    <joint name="meca_axis_5_joint" type="revolute">
        <origin rpy="0 0 0" xyz="0.12 0 0" />
        <parent link="meca_axis_4_link" />
        <child link="meca_axis_5_link" />
        <axis xyz="0 1 0" />
        <limit effort="10.0" lower="-2.00713" upper="2.00713" velocity="5.23599" />
    </joint>
    <!-- Joint 6 -->
    <link name="meca_axis_6_link">
        <visual>
            <origin rpy="0 0 0" xyz="0 0 0" />
            <geometry>
                <mesh filename="package://mecademic_description/meshes/meca_500_r3_j6.dae" />
            </geometry>
        </visual>
        <collision>
            <origin rpy="0 0 0" xyz="0 0 0" />
            <geometry>
                <mesh filename="package://mecademic_description/meshes/meca_500_r3_j6_collision.stl" />
            </geometry>
        </collision>

        <inertial>
            <mass value="0.1" />
            <inertia ixx="0.03" ixy="0.0" ixz="0.0" iyy="0.03" iyz="0.0" izz="0.03" />
        </inertial>

    </link>
    <joint name="meca_axis_6_joint" type="revolute">
        <origin rpy="0 0 0" xyz="0.07 0 0" />
        <parent link="meca_axis_5_link" />
        <child link="meca_axis_6_link" />
        <axis xyz="1 0 0" />
        <limit effort="10.0" lower="-3.14159" upper="3.14159" velocity="8.72665" />
    </joint>
    <!-- <link name="meca_axis_flange" /> -->
    <!-- <joint name="meca_axis_joint_7-flange" type="fixed">
        <origin rpy="0 0 0" xyz="0 0 0" />
        <parent link="meca_axis_6_link" />
        <child link="meca_axis_flange" />
    </joint> -->
    <!-- ROS-Industrial 'tool0' frame: all-zeros tool frame -->
    <!-- <link name="meca_axis_tool0" /> -->
    <!-- <joint name="meca_axis_link_7-tool0" type="fixed">
        <origin rpy="3.14159265359 -1.57079632679 0" xyz="0 0 0" />
        <parent link="meca_axis_flange" />
        <child link="meca_axis_tool0" />
    </joint> -->
    <!-- End Effector -->
    <joint name="meca_hand_joint" type="fixed">
        <parent link="meca_axis_6_link" />
        <child link="meca_hand" />
        <origin rpy="0 1.57079632679 0" xyz="0 0 0" />
    </joint>
    <link name="meca_hand">
        <visual>
            <geometry>
                <mesh filename="package://mecademic_description/meshes/hand.dae" />
            </geometry>
        </visual>
        <collision>
            <origin rpy="0 1.57079632679 1.57079632679" xyz="0 0 0.03" />
            <geometry>
                <box size="0.07 0.04 0.2" />
            </geometry>
        </collision>


        <inertial>
            <mass value="0.1" />
            <inertia ixx="0.03" iyy="0.03" izz="0.03" ixy="0.0" ixz="0.0" iyz="0.0" />
        </inertial>

    </link>
    <link name="meca_leftfinger">
        <visual>
            <geometry>
                <mesh filename="package://mecademic_description/meshes/finger.dae" />
            </geometry>
        </visual>
        <inertial>
            <mass value="0.1" />
            <!-- <origin xyz="0 0.0145644 0.0227941" rpy="0 0 0" /> -->
            <inertia ixx="3.01220925051e-05" ixy="0.0" ixz="0.0" iyy="2.95873808038e-05" iyz="0.0" izz="6.95125211657e-06" />
            <!-- <inertia ixx="0.03" iyy="0.03" izz="0.03" ixy="0.0" ixz="0.0" iyz="0.0" /> -->
        </inertial>
        <collision>
            <origin rpy="0 0 0" xyz="0 0 0" />
            <geometry>
                <mesh filename="package://mecademic_description/meshes/finger.dae" />
            </geometry>
        </collision>
    </link>
    <link name="meca_rightfinger">
        <visual>
            <origin rpy="0 0 3.14159265359" xyz="0 0 0" />
            <geometry>
                <mesh filename="package://mecademic_description/meshes/finger.dae" />
            </geometry>

        </visual>
        <inertial>
            <mass value="0.1" />
            <!-- <origin xyz="0 0.0145644 0.0227941" rpy="0 0 ${pi}" /> -->
            <inertia ixx="3.01220925051e-05" ixy="0.0" ixz="0.0" iyy="2.95873808038e-05" iyz="0.0" izz="6.95125211657e-06" />
            <!-- <inertia ixx="0.03" iyy="0.03" izz="0.03" ixy="0.0" ixz="0.0" iyz="0.0" /> -->
        </inertial>
        <collision>
            <origin rpy="0 0 3.14159265359" xyz="0 0 0" />
            <geometry>
                <mesh filename="package://mecademic_description/meshes/finger.dae" />
            </geometry>
        </collision>
    </link>
    <joint name="meca_finger_joint1" type="prismatic">
        <parent link="meca_hand" />
        <child link="meca_leftfinger" />
        <origin rpy="0 0 0" xyz="0 0 0.0584" />
        <axis xyz="0 1 0" />
        <limit effort="10" lower="-0.001" upper="0.04" velocity="0.3" />
    </joint>
    <joint name="meca_finger_joint2" type="prismatic">
        <parent link="meca_hand" />
        <child link="meca_rightfinger" />
        <origin rpy="0 0 0" xyz="0 0 0.0584" />
        <axis xyz="0 -1 0" />
        <limit effort="10" lower="-0.001" upper="0.04" velocity="0.3" />
        <mimic joint="meca_finger_joint1" />
    </joint>

    <transmission name="trans_meca_axis_1_joint">
        <type>transmission_interface/SimpleTransmission</type>
        <joint name="meca_axis_1_joint">
            <hardwareInterface>hardware_interface/EffortJointInterface</hardwareInterface>
        </joint>
        <actuator name="meca_axis_1_joint_motor">
            <hardwareInterface>hardware_interface/EffortJointInterface</hardwareInterface>
            <mechanicalReduction>1</mechanicalReduction>
        </actuator>
    </transmission>
    <transmission name="trans_meca_axis_2_joint">
        <type>transmission_interface/SimpleTransmission</type>
        <joint name="meca_axis_2_joint">
            <hardwareInterface>hardware_interface/EffortJointInterface</hardwareInterface>
        </joint>
        <actuator name="meca_axis_2_joint_motor">
            <hardwareInterface>hardware_interface/EffortJointInterface</hardwareInterface>
            <mechanicalReduction>1</mechanicalReduction>
        </actuator>
    </transmission>
    <transmission name="trans_meca_axis_3_joint">
        <type>transmission_interface/SimpleTransmission</type>
        <joint name="meca_axis_3_joint">
            <hardwareInterface>hardware_interface/EffortJointInterface</hardwareInterface>
        </joint>
        <actuator name="meca_axis_3_joint_motor">
            <hardwareInterface>hardware_interface/EffortJointInterface</hardwareInterface>
            <mechanicalReduction>1</mechanicalReduction>
        </actuator>
    </transmission>
    <transmission name="trans_meca_axis_4_joint">
        <type>transmission_interface/SimpleTransmission</type>
        <joint name="meca_axis_4_joint">
            <hardwareInterface>hardware_interface/EffortJointInterface</hardwareInterface>
        </joint>
        <actuator name="meca_axis_4_joint_motor">
            <hardwareInterface>hardware_interface/EffortJointInterface</hardwareInterface>
            <mechanicalReduction>1</mechanicalReduction>
        </actuator>
    </transmission>
    <transmission name="trans_meca_axis_5_joint">
        <type>transmission_interface/SimpleTransmission</type>
        <joint name="meca_axis_5_joint">
            <hardwareInterface>hardware_interface/EffortJointInterface</hardwareInterface>
        </joint>
        <actuator name="meca_axis_5_joint_motor">
            <hardwareInterface>hardware_interface/EffortJointInterface</hardwareInterface>
            <mechanicalReduction>1</mechanicalReduction>
        </actuator>
    </transmission>
    <transmission name="trans_meca_axis_6_joint">
        <type>transmission_interface/SimpleTransmission</type>
        <joint name="meca_axis_6_joint">
            <hardwareInterface>hardware_interface/EffortJointInterface</hardwareInterface>
        </joint>
        <actuator name="meca_axis_6_joint_motor">
            <hardwareInterface>hardware_interface/EffortJointInterface</hardwareInterface>
            <mechanicalReduction>1</mechanicalReduction>
        </actuator>
    </transmission>
    <transmission name="trans_meca_finger_joint1">
        <type>transmission_interface/SimpleTransmission</type>
        <joint name="meca_finger_joint1">
            <hardwareInterface>hardware_interface/EffortJointInterface</hardwareInterface>
        </joint>
        <actuator name="meca_finger_joint1_motor">
            <hardwareInterface>hardware_interface/EffortJointInterface</hardwareInterface>
            <mechanicalReduction>1</mechanicalReduction>
        </actuator>
    </transmission>
    <transmission name="trans_meca_finger_joint2">
        <type>transmission_interface/SimpleTransmission</type>
        <joint name="meca_finger_joint2">
            <hardwareInterface>hardware_interface/EffortJointInterface</hardwareInterface>
        </joint>
        <actuator name="meca_finger_joint2_motor">
            <hardwareInterface>hardware_interface/EffortJointInterface</hardwareInterface>
            <mechanicalReduction>1</mechanicalReduction>
        </actuator>
    </transmission>
    <gazebo>
        <plugin name="gazebo_ros_control" filename="libgazebo_ros_control.so">
            <!-- <robotNamespace>/robot1</robotNamespace> -->
        </plugin>
    </gazebo>
    <gazebo>
        <plugin name="mimic_joint_plugin" filename="libroboticsgroup_upatras_gazebo_mimic_joint_plugin.so">
            <joint>meca_finger_joint1</joint>
            <mimicJoint>meca_finger_joint2</mimicJoint>
            <!-- <robotNamespace>/</robotNamespace> -->
        </plugin>
    </gazebo>
    <gazebo reference="meca_rightfinger">
        <mu1>100</mu1>
        <mu2>100</mu2>
        <kp>100000</kp>
        <!-- <fdir1>0 0 0</fdir1> -->
        <collision name="meca_leftfinger_collision">
            <surface>
                <friction>
                    <torsional>
                        <coefficient>100</coefficient>
                        <use_patch_radius>true</use_patch_radius>
                        <patch_radius>0.1</patch_radius>
                        <surface_radius>0.1</surface_radius>
                    </torsional>
                </friction>
            </surface>
        </collision>
    </gazebo>
    <gazebo reference="meca_leftfinger">
        <mu1>100</mu1>
        <mu2>100</mu2>
        <kp>100000</kp>
        <!-- <fdir1>0 0 0</fdir1> -->
        <collision name="meca_rightfinger_collision">
            <surface>
                <friction>
                    <torsional>
                        <coefficient>100</coefficient>
                        <use_patch_radius>true</use_patch_radius>
                        <patch_radius>0.1</patch_radius>
                        <surface_radius>0.1</surface_radius>
                    </torsional>
                </friction>
            </surface>
        </collision>
    </gazebo>
    <!-- <gazebo reference="meca_finger_joint1">
        <implicitSpringDamper>1</implicitSpringDamper>
    </gazebo>
    <gazebo reference="meca_finger_joint2">
        <implicitSpringDamper>1</implicitSpringDamper>
    </gazebo> -->
    <!-- <gazebo>
        <plugin name="gazebo_grasp_fix" filename="libgazebo_grasp_fix.so">
            <arm>
                <arm_name>meca_arm</arm_name>
                <palm_link>meca_axis_6_link</palm_link>
                <gripper_link>meca_leftfinger</gripper_link>
                <gripper_link> meca_rightfinger </gripper_link>

            </arm>
            <forces_angle_tolerance>100</forces_angle_tolerance>
            <update_rate>4</update_rate>
            <grip_count_threshold>4</grip_count_threshold>
            <max_grip_count>8</max_grip_count>
            <release_tolerance>0.005</release_tolerance>
            <disable_collisions_on_attach>false</disable_collisions_on_attach>
            <contact_topic>__default_topic__</contact_topic>
        </plugin>
    </gazebo> -->

</robot>